<robot
  name="r_arm">
  <link
    name="base_link">
  </link>
  <joint
    name="r_shoulder_y"
    type="revolute">
    <origin
      xyz="0.016 -0.06 0.45"
      rpy="0 -1.5707963267949 3.14159265358979">
    </origin>
    <parent link="base_link" />
    <child link="r_shoulder" />
    <axis xyz="0 -1 0" />
  </joint>
  <link
    name="r_shoulder">
  </link>
  <joint
    name="r_shoulder_x"
    type="revolute">
    <origin
      xyz="0 0.0284 0"
      rpy="3.14159265358979 0 -1.5707963267949">
    </origin>
    <parent link="r_shoulder" />
    <child link="r_shoulder_motor" />
    <axis xyz="0 0 -1" />
  </joint>
  <link
    name="r_shoulder_motor">
  </link>
  <joint
    name="r_arm_z"
    type="revolute">
    <origin
      xyz="0 0.03625 0.0185000000000002"
      rpy="0 0 0">
    </origin>
    <parent link="r_shoulder_motor" />
    <child link="r_upper_arm" />
    <axis xyz="0 1 0" />
  </joint>
  <link
    name="r_upper_arm">
  </link>
  <joint
    name="r_elbow_y"
    type="revolute">
    <origin
      xyz="0 0.11175 -0.01"
      rpy="0 0 0">
    </origin>
    <parent link="r_upper_arm" />
    <child link="r_forearm" />
    <axis xyz="1 0 0" />
  </joint>
  <link
    name="r_forearm">
  </link>
  <joint
    name="r_wrist_z"
    type="revolute">
    <origin
      xyz="-0.00691480023011085 0.14715758721324 -0.00499021473883754"
      rpy="0 0 0">
    </origin>
    <parent link="r_forearm" />
    <child link="r_gripper_base" />
    <axis xyz="0 1 0" />
  </joint>
  <link
    name="r_gripper_base">
  </link>
  <joint
    name="r_gripper"
    type="revolute">
    <origin
      xyz="-0.011 0.11 0"
      rpy="0 0 0">
    </origin>
    <parent link="r_gripper_base" />
    <child link="r_gripper_center" />
    <axis xyz="0 0 -1" />
  </joint>
</robot>